Workbook
Name M: intro.dat!$H$39

Sheet poll_iss_ag (1)
B1: species_code | C1: sex | D1: sex_desc | E1: iss | F1: nss | G1: nhls | H1: Last year | M1: Last year | N1: This year | P1: year | Q1: age_iss
A2: 1982 | B2: 21740 | C2: 4 | D2: total_post | E2: 162.03932 | F2: 1500 | G2: 81 | H2: 77.141593 | I2: 162.03932 | K2: 105 | L2: 77.141593 | M2: 213.66323 | N2: 162.03932 | P2: 1982 | Q2: 213.66323
A3: 1983 | B3: 21740 | C3: 4 | D3: total_post | E3: 130.70066 | F3: 1931 | G3: 95 | H3: 23.712741 | I3: 130.70066 | K3: 126 | L3: 23.712741 | M3: 65.678457 | N3: 130.70066 | P3: 1983 | Q3: 65.678457
A4: 1984 | B4: 21740 | C4: 4 | D4: total_post | E4: 63.273125 | F4: 1806 | G4: 116 | H4: 111.97117 | I4: 63.273125 | K4: 118 | L4: 111.97117 | M4: 310.13259 | N4: 63.273125 | P4: 1984 | Q4: 310.13259
A5: 1985 | B5: 21740 | C5: 4 | D5: total_post | E5: 73.535708 | F5: 1890 | G5: 81 | H5: 30.772516 | I5: 73.535708 | K5: 125 | L5: 30.772516 | M5: 85.232299 | N5: 73.535708 | P5: 1985 | Q5: 85.232299
A6: 1986 | B6: 21740 | C6: 4 | D6: total_post | E6: 151.94817 | F6: 1344 | G6: 45 | H6: 72.783656 | I6: 151.94817 | K6: 88 | L6: 72.783656 | M6: 201.59282 | N6: 151.94817 | P6: 1986 | Q6: 201.59282
A7: 1987 | B7: 21740 | C7: 4 | D7: total_post | E7: 61.2147 | F7: 1547 | G7: 34 | H7: 70.687438 | I7: 61.2147 | K7: 105 | L7: 70.687438 | M7: 195.78681 | N7: 61.2147 | P7: 1987 | Q7: 195.78681
A8: 1988 | B8: 21740 | C8: 4 | D8: total_post | E8: 82.232544 | F8: 1173 | G8: 26 | H8: 61.966137 | I8: 82.232544 | K8: 76 | L8: 61.966137 | M8: 171.63095 | N8: 82.232544 | P8: 1988 | Q8: 171.63095
A9: 1989 | B9: 21740 | C9: 4 | D9: total_post | E9: 53.19137 | F9: 1227 | G9: 38 | H9: 95.43097 | I9: 53.19137 | K9: 80 | L9: 95.43097 | M9: 264.32031 | N9: 53.19137 | P9: 1989 | Q9: 264.32031
A10: 1990 | B10: 21740 | C10: 4 | D10: total_post | E10: 48.266322 | F10: 1257 | G10: 46 | H10: 82.804945 | I10: 48.266322 | K10: 82 | L10: 82.804945 | M10: 229.34932 | N10: 48.266322 | P10: 1990 | Q10: 229.34932
A11: 1991 | B11: 21740 | C11: 4 | D11: total_post | E11: 79.424272 | F11: 1063 | G11: 46 | H11: 65.196175 | I11: 79.424272 | K11: 71 | L11: 65.196175 | M11: 180.57736 | N11: 79.424272 | P11: 1991 | Q11: 180.57736
A12: 1992 | B12: 21740 | C12: 4 | D12: total_post | E12: 85.220464 | F12: 1263 | G12: 30 | H12: 40.844997 | I12: 85.220464 | K12: 82 | L12: 40.844997 | M12: 113.13059 | N12: 85.220464 | P12: 1992 | Q12: 113.13059
A13: 1993 | B13: 21740 | C13: 4 | D13: total_post | E13: 91.983614 | F13: 1385 | G13: 33 | H13: 43.043603 | I13: 91.983614 | K13: 90 | L13: 43.043603 | M13: 119.22019 | N13: 91.983614 | P13: 1993 | Q13: 119.22019
... A41: 2022 | B41: 21740 | C41: 4 | D41: total_post | E41: 172.8341 | F41: 1980 | G41: 448 | H41: 163.39779 | I41: 172.8341 | K41: 100 | L41: 163.39779 | M41: 452.57169 | N41: 172.8341 | P41: 2022 | Q41: 452.57169
A42: 2023 | B42: 21740 | C42: 4 | D42: total_post | E42: 126.77731 | F42: 1677 | G42: 347 | H42: 147.67417 | I42: 126.77731 | K42: 100 | L42: 147.67417 | N42: 126.77731
A43: 2024 | B43: 21740 | C43: 4 | D43: total_post | E43: 64.214082 | F43: 1526 | G43: 325 | H43: 150 | I43: 64.214082 | N43: 64.214082

Sheet pm_25.dat
B1: #styr
B2: 1964
B3: #styr_bts
B4: 1982
B5: #styr_ats
B6: 1994
B7: #endyr
B8: 2025
B9: #recage
B10: 1
B11: #nages
B12: 15
B13: #p_mature
B14: 0 | C14: 0.008 | D14: 0.289 | E14: 0.641 | F14: 0.842 | G14: 0.901 | H14: 0.947 | I14: 0.963 | J14: 0.97 | K14: 1 | L14: 1 | M14: 1 | N14: 1 | O14: 1 | P14: 1
B15: #ew_ind
B16: 8 | C16: 7 | D16: 2 | E16: 9 | F16: 7 | G16: 7 | H16: 7 | I16: 7 | J16: 8 | K16: 6 | L16: 5 | M16: 7 | N16: 8 | O16: 8 | P16: 7 | Q16: 5 | R16: 4 | S16: 6 | T16: 7 | U16: 8 | V16: 3 | W16: 7 | X16: 7 | Y16: 7 | Z16: 7 | AA16: 8 | AB16: 4 | AC16: 6 | AD16: 2 | AE16: 1 | AF16: 6 | AG16: 6 | AH16: 4 | AI16: 4 | AJ16: 10 | AK16: 4 | AL16: 4 | AM16: 4 | AN16: 4 | AO16: 4 | AP16: 4 | AQ16: 4 | AR16: 4 | AS16: 4 | AT16: 4 | AU16: 4 | AV16: 4 | AW16: 4 | AX16: 4 | AY16: 4 | AZ16: 4 | BA16: 4 | BB16: 4 | BC16: 4 | BD16: 4 | BE16: 4 | BF16: 4 | BG16: 4 | BH16: 4 | BI16: 4 | BJ16: 4
B17: 5 | C17: 6 | D17: 6 | E17: 8 | F17: 5 | G17: 8 | H17: 5 | I17: 4 | J17: 8 | K17: 4 | L17: 5 | M17: 5 | N17: 6 | O17: 5 | P17: 8 | Q17: 11 | R17: 6 | S17: 7 | T17: 9 | U17: 10 | V17: 4 | W17: 4 | X17: 6 | Y17: 5 | Z17: 7 | AA17: 9 | AB17: 5 | AC17: 7 | AD17: 3 | AE17: 5 | AF17: 3 | AG17: 5 | AH17: 4 | AI17: 6 | AJ17: 11 | AK17: 4 | AL17: 4 | AM17: 4 | AN17: 4 | AO17: 4 | AP17: 4 | AQ17: 4 | AR17: 4 | AS17: 4 | AT17: 4 | AU17: 4 | AV17: 4 | AW17: 4 | AX17: 4 | AY17: 4 | AZ17: 4 | BA17: 4 | BB17: 4 | BC17: 4 | BD17: 4 | BE17: 4 | BF17: 4 | BG17: 4 | BH17: 4 | BI17: 4 | BJ17: 4
B18: #wt_fsh
A19: 1964 | B19: 0.0066 | C19: 0.17 | D19: 0.303 | E19: 0.447 | F19: 0.589 | G19: 0.722 | H19: 0.84 | I19: 0.942 | J19: 1.029 | K19: 1.102 | L19: 1.163 | M19: 1.212 | N19: 1.253 | O19: 1.286 | P19: 1.312
A20: =A19+1 -> 1965 | B20: 0.0066 | C20: 0.17 | D20: 0.303 | E20: 0.447 | F20: 0.589 | G20: 0.722 | H20: 0.84 | I20: 0.942 | J20: 1.029 | K20: 1.102 | L20: 1.163 | M20: 1.212 | N20: 1.253 | O20: 1.286 | P20: 1.312
A21: =A20+1 -> 1966 | B21: 0.0066 | C21: 0.17 | D21: 0.303 | E21: 0.447 | F21: 0.589 | G21: 0.722 | H21: 0.84 | I21: 0.942 | J21: 1.029 | K21: 1.102 | L21: 1.163 | M21: 1.212 | N21: 1.253 | O21: 1.286 | P21: 1.312
A22: =A21+1 -> 1967 | B22: 0.0066 | C22: 0.17 | D22: 0.303 | E22: 0.447 | F22: 0.589 | G22: 0.722 | H22: 0.84 | I22: 0.942 | J22: 1.029 | K22: 1.102 | L22: 1.163 | M22: 1.212 | N22: 1.253 | O22: 1.286 | P22: 1.312
A23: =A22+1 -> 1968 | B23: 0.0066 | C23: 0.17 | D23: 0.303 | E23: 0.447 | F23: 0.589 | G23: 0.722 | H23: 0.84 | I23: 0.942 | J23: 1.029 | K23: 1.102 | L23: 1.163 | M23: 1.212 | N23: 1.253 | O23: 1.286 | P23: 1.312
A24: =A23+1 -> 1969 | B24: 0.0066 | C24: 0.17 | D24: 0.303 | E24: 0.447 | F24: 0.589 | G24: 0.722 | H24: 0.84 | I24: 0.942 | J24: 1.029 | K24: 1.102 | L24: 1.163 | M24: 1.212 | N24: 1.253 | O24: 1.286 | P24: 1.312
A25: =A24+1 -> 1970 | B25: 0.0066 | C25: 0.17 | D25: 0.303 | E25: 0.447 | F25: 0.589 | G25: 0.722 | H25: 0.84 | I25: 0.942 | J25: 1.029 | K25: 1.102 | L25: 1.163 | M25: 1.212 | N25: 1.253 | O25: 1.286 | P25: 1.312
A26: =A25+1 -> 1971 | B26: 0.0066 | C26: 0.17 | D26: 0.303 | E26: 0.447 | F26: 0.589 | G26: 0.722 | H26: 0.84 | I26: 0.942 | J26: 1.029 | K26: 1.102 | L26: 1.163 | M26: 1.212 | N26: 1.253 | O26: 1.286 | P26: 1.312
A27: =A26+1 -> 1972 | B27: 0.0066 | C27: 0.17 | D27: 0.303 | E27: 0.447 | F27: 0.589 | G27: 0.722 | H27: 0.84 | I27: 0.942 | J27: 1.029 | K27: 1.102 | L27: 1.163 | M27: 1.212 | N27: 1.253 | O27: 1.286 | P27: 1.312
A28: =A27+1 -> 1973 | B28: 0.0066 | C28: 0.17 | D28: 0.303 | E28: 0.447 | F28: 0.589 | G28: 0.722 | H28: 0.84 | I28: 0.942 | J28: 1.029 | K28: 1.102 | L28: 1.163 | M28: 1.212 | N28: 1.253 | O28: 1.286 | P28: 1.312
A29: =A28+1 -> 1974 | B29: 0.0066 | C29: 0.17 | D29: 0.303 | E29: 0.447 | F29: 0.589 | G29: 0.722 | H29: 0.84 | I29: 0.942 | J29: 1.029 | K29: 1.102 | L29: 1.163 | M29: 1.212 | N29: 1.253 | O29: 1.286 | P29: 1.312
A30: =A29+1 -> 1975 | B30: 0.0066 | C30: 0.17 | D30: 0.303 | E30: 0.447 | F30: 0.589 | G30: 0.722 | H30: 0.84 | I30: 0.942 | J30: 1.029 | K30: 1.102 | L30: 1.163 | M30: 1.212 | N30: 1.253 | O30: 1.286 | P30: 1.312
A31: =A30+1 -> 1976 | B31: 0.0066 | C31: 0.17 | D31: 0.303 | E31: 0.447 | F31: 0.589 | G31: 0.722 | H31: 0.84 | I31: 0.942 | J31: 1.029 | K31: 1.102 | L31: 1.163 | M31: 1.212 | N31: 1.253 | O31: 1.286 | P31: 1.312
... A79: =A78+1 -> 2024 | B79: 0.025182262 | C79: 0.18622176 | D79: 0.401336 | E79: 0.667373 | F79: 0.662504 | G79: 0.719546 | H79: 0.790729 | I79: 0.905068 | J79: 1.009136 | K79: 1.061077 | L79: 1.138288 | M79: 1.257056 | N79: 1.267343 | O79: 1.289913 | P79: 1.368254
B81: #wt_ssb
A82: 1964 | B82: 0.084881666 | C82: 0.19586813 | D82: 0.31376279 | E82: 0.45929554 | F82: 0.5886236 | G82: 0.69781833 | H82: 0.79679874 | I82: 0.91486126 | J82: 1.056957 | K82: 1.1472315 | L82: 1.2901065 | M82: 1.3879179 | N82: 1.4316668 | O82: 1.4070027 | P82: 1.5228669
A83: =A82+1 -> 1965 | B83: 0.084881666 | C83: 0.19586813 | D83: 0.31376279 | E83: 0.45929554 | F83: 0.5886236 | G83: 0.69781833 | H83: 0.79679874 | I83: 0.91486126 | J83: 1.056957 | K83: 1.1472315 | L83: 1.2901065 | M83: 1.3879179 | N83: 1.4316668 | O83: 1.4070027 | P83: 1.5228669
A84: =A83+1 -> 1966 | B84: 0.084881666 | C84: 0.19586813 | D84: 0.31376279 | E84: 0.45929554 | F84: 0.5886236 | G84: 0.69781833 | H84: 0.79679874 | I84: 0.91486126 | J84: 1.056957 | K84: 1.1472315 | L84: 1.2901065 | M84: 1.3879179 | N84: 1.4316668 | O84: 1.4070027 | P84: 1.5228669
A85: =A84+1 -> 1967 | B85: 0.084881666 | C85: 0.19586813 | D85: 0.31376279 | E85: 0.45929554 | F85: 0.5886236 | G85: 0.69781833 | H85: 0.79679874 | I85: 0.91486126 | J85: 1.056957 | K85: 1.1472315 | L85: 1.2901065 | M85: 1.3879179 | N85: 1.4316668 | O85: 1.4070027 | P85: 1.5228669
A86: =A85+1 -> 1968 | B86: 0.084881666 | C86: 0.19586813 | D86: 0.31376279 | E86: 0.45929554 | F86: 0.5886236 | G86: 0.69781833 | H86: 0.79679874 | I86: 0.91486126 | J86: 1.056957 | K86: 1.1472315 | L86: 1.2901065 | M86: 1.3879179 | N86: 1.4316668 | O86: 1.4070027 | P86: 1.5228669
A87: =A86+1 -> 1969 | B87: 0.084881666 | C87: 0.19586813 | D87: 0.31376279 | E87: 0.45929554 | F87: 0.5886236 | G87: 0.69781833 | H87: 0.79679874 | I87: 0.91486126 | J87: 1.056957 | K87: 1.1472315 | L87: 1.2901065 | M87: 1.3879179 | N87: 1.4316668 | O87: 1.4070027 | P87: 1.5228669
A88: =A87+1 -> 1970 | B88: 0.084881666 | C88: 0.19586813 | D88: 0.311072 | E88: 0.427458 | F88: 0.55009 | G88: 0.674562 | H88: 0.797415 | I88: 0.916081 | J88: 1.028772 | K88: 1.134344 | L88: 1.232157 | M88: 1.321963 | N88: 1.403799 | O88: 1.477905 | P88: 1.544656
...

Sheet Tables
A2: Year | B2: & | C2: Bairdi& | D2: Chinook& | E2: Halib | F2: & | G2: Halib.M& | H2: Herring | I2: & | J2: NonChin& | K2: Snow | L2: Crab | M2: & | N2: Red | O2: King | P2: & | Q2: Blue | R2: King& | S2: Goldn | T2: King\\
B3: \hline
B4: 1991 | C4: & | D4: 1397836 | E4: & | F4: 36348 | G4: & | H4: 2155 | I4: & | J4: NA | K4: & | L4: 3158 | M4: & | N4: 28657 | O4: & | P4: 4378007 | Q4: & | R4: 17777 | S4: & | T4: NA | U4: & | V4: NA | W4: \\
B5: 1992 | C5: & | D5: 1500764 | E5: & | F5: 33672 | G5: & | H5: 2220 | I5: & | J5: NA | K5: & | L5: 646 | M5: & | N5: 40186 | O5: & | P5: 4569662 | Q5: & | R5: 43873 | S5: & | T5: NA | U5: & | V5: NA | W5: \\
B6: 1993 | C6: & | D6: 1649086 | E6: & | F6: 36615 | G6: & | H6: 1326 | I6: & | J6: NA | K6: & | L6: 527 | M6: & | N6: 241971 | O6: & | P6: 738250 | Q6: & | R6: 58139 | S6: & | T6: NA | U6: & | V6: NA | W6: \\
B7: 1994 | C7: & | D7: 371213 | E7: & | F7: 31880 | G7: & | H7: 963 | I7: & | J7: 688 | K7: & | L7: 1626 | M7: & | N7: 91764 | O7: & | P7: 811733 | Q7: & | R7: 42360 | S7: & | T7: NA | U7: & | V7: NA | W7: \\
B8: 1995 | C8: & | D8: 153992 | E8: & | F8: 13403 | G8: & | H8: 491 | I8: & | J8: 397 | K8: & | L8: 904 | M8: & | N8: 17754 | O8: & | P8: 206651 | Q8: & | R8: 4644 | S8: & | T8: NA | U8: & | V8: NA | W8: \\
B9: 1996 | C9: & | D9: 89415 | E9: & | F9: 55467 | G9: & | H9: 382 | I9: & | J9: 320 | K9: & | L9: 1241 | M9: & | N9: 77173 | O9: & | P9: 63398 | Q9: & | R9: 5933 | S9: & | T9: NA | U9: & | V9: NA | W9: \\
B10: 1997 | C10: & | D10: 17046 | E10: & | F10: 44312 | G10: & | H10: 257 | I10: & | J10: 200 | K10: & | L10: 1134 | M10: & | N10: 65414 | O10: & | P10: 216152 | Q10: & | R10: 137 | S10: & | T10: NA | U10: & | V10: NA | W10: \\
B11: 1998 | C11: & | D11: 57036 | E11: & | F11: 51244 | G11: & | H11: 352 | I11: & | J11: 278 | K11: & | L11: 800 | M11: & | N11: 60676 | O11: & | P11: 123400 | Q11: & | R11: 14286 | S11: & | T11: NA | U11: & | V11: NA | W11: \\
B12: 1999 | C12: & | D12: 2397 | E12: & | F12: 10381 | G12: & | H12: 153 | I12: & | J12: 124 | K12: & | L12: 799 | M12: & | N12: 44610 | O12: & | P12: 15829 | Q12: & | R12: 90 | S12: & | T12: NA | U12: & | V12: NA | W12: \\
B13: 2000 | C13: & | D13: 1484 | E13: & | F13: 4242 | G13: & | H13: 110 | I13: & | J13: 90 | K13: & | L13: 482 | M13: & | N13: 56866 | O13: & | P13: 6480 | Q13: & | R13: 0 | S13: & | T13: NA | U13: & | V13: NA | W13: \\
B14: 2001 | C14: & | D14: 5060 | E14: & | F14: 30933 | G14: & | H14: 242 | I14: & | J14: 199 | K14: & | L14: 225 | M14: & | N14: 53901 | O14: & | P14: 5653 | Q14: & | R14: 105 | S14: & | T14: NA | U14: & | V14: NA | W14: \\
B15: 2002 | C15: & | D15: 2112 | E15: & | F15: 32381 | G15: & | H15: 165 | I15: & | J15: 137 | K15: & | L15: 108 | M15: & | N15: 77167 | O15: & | P15: 2697 | Q15: & | R15: 16 | S15: & | T15: NA | U15: & | V15: NA | W15: \\
B16: 2003 | C16: & | D16: 732 | E16: & | F16: 43095 | G16: & | H16: 88 | I16: & | J16: 74 | K16: & | L16: 967 | M16: & | N16: 179987 | O16: & | P16: 608 | Q16: & | R16: 52 | S16: & | T16: 8 | U16: & | V16: NA | W16: \\
B17: 2004 | C17: & | D17: 1091 | E17: & | F17: 48799 | G17: & | H17: 96 | I17: & | J17: 81 | K17: & | L17: 1095 | M17: & | N17: 441188 | O17: & | P17: 640 | Q17: & | R17: 26 | S17: & | T17: 4 | U17: & | V17: 1 | W17: \\
B18: 2005 | C18: & | D18: 601 | E18: & | F18: 66208 | G18: & | H18: 119 | I18: & | J18: 100 | K18: & | L18: 593 | M18: & | N18: 703076 | O18: & | P18: 2016 | Q18: & | R18: 0 | S18: & | T18: NA | U18: & | V18: 1 | W18: \\
B19: 2006 | C19: & | D19: 1288 | E19: & | F19: 80915 | G19: & | H19: 132 | I19: & | J19: 111 | K19: & | L19: 433 | M19: & | N19: 305793 | O19: & | P19: 2567 | Q19: & | R19: 288 | S19: & | T19: NA | U19: & | V19: 3 | W19: \\
B20: 2007 | C20: & | D20: 1465 | E20: & | F20: 116329 | G20: & | H20: 312 | I20: & | J20: 269 | K20: & | L20: 351 | M20: & | N20: 86380 | O20: & | P20: 3033 | Q20: & | R20: 7 | S20: & | T20: NA | U20: & | V20: 3 | W20: \\
B21: 2008 | C21: & | D21: 9025 | E21: & | F21: 20602 | G21: & | H21: 373 | I21: & | J21: 311 | K21: & | L21: 127 | M21: & | N21: 15119 | O21: & | P21: 8894 | Q21: & | R21: 670 | S21: & | T21: 8 | U21: & | V21: 33 | W21: \\
B22: 2009 | C22: & | D22: 6155 | E22: & | F22: 12284 | G22: & | H22: 541 | I22: & | J22: 436 | K22: & | L22: 64 | M22: & | N22: 45960 | O22: & | P22: 7312 | Q22: & | R22: 1136 | S22: & | T22: 19 | U22: & | V22: NA | W22: \\
B23: 2010 | C23: & | D23: 12787 | E23: & | F23: 9833 | G23: & | H23: 335 | I23: & | J23: 267 | K23: & | L23: 348 | M23: & | N23: 13728 | O23: & | P23: 9444 | Q23: & | R23: 1122 | S23: & | T23: 28 | U23: & | V23: NA | W23: \\
B24: 2011 | C24: & | D24: 10973 | E24: & | F24: 25499 | G24: & | H24: 459 | I24: & | J24: 378 | K24: & | L24: 376 | M24: & | N24: 193754 | O24: & | P24: 6493 | Q24: & | R24: 577 | S24: & | T24: 25 | U24: & | V24: NA | W24: \\
B25: 2012 | C25: & | D25: 5620 | E25: & | F25: 11343 | G25: & | H25: 462 | I25: & | J25: 388 | K25: & | L25: 2352 | M25: & | N25: 22297 | O25: & | P25: 6189 | Q25: & | R25: 343 | S25: & | T25: NA | U25: & | V25: NA | W25: \\
B26: 2013 | C26: & | D26: 12426 | E26: & | F26: 13091 | G26: & | H26: 333 | I26: & | J26: 271 | K26: & | L26: 958 | M26: & | N26: 125525 | O26: & | P26: 8605 | Q26: & | R26: 507 | S26: & | T26: 34 | U26: & | V26: 107 | W26: \\
B27: 2014 | C27: & | D27: 12521 | E27: & | F27: 15135 | G27: & | H27: 239 | I27: & | J27: 199 | K27: & | L27: 159 | M27: & | N27: 219837 | O27: & | P27: 19454 | Q27: & | R27: 368 | S27: & | T27: NA | U27: & | V27: NA | W27: \\
B28: 2015 | C28: & | D28: 8872 | E28: & | F28: 18329 | G28: & | H28: 152 | I28: & | J28: 130 | K28: & | L28: 1487 | M28: & | N28: 237776 | O28: & | P28: 8339 | Q28: & | R28: 0 | S28: & | T28: NA | U28: & | V28: NA | W28: \\
B29: 2016 | C29: & | D29: 2295 | E29: & | F29: 22204 | G29: & | H29: 121 | I29: & | J29: 102 | K29: & | L29: 1431 | M29: & | N29: 343208 | O29: & | P29: 1166 | Q29: & | R29: 439 | S29: & | T29: NA | U29: & | V29: 26 | W29: \\
B30: 2017 | C30: & | D30: 7269 | E30: & | F30: 30078 | G30: & | H30: 97 | I30: & | J30: 88 | K30: & | L30: 963 | M30: & | N30: 467750 | O30: & | P30: 3406 | Q30: & | R30: 202 | S30: & | T30: 0 | U30: & | V30: 67 | W30: \\
B31: 2018 | C31: & | D31: 2249 | E31: & | F31: 13726 | G31: & | H31: 75 | I31: & | J31: 62 | K31: & | L31: 474 | M31: & | N31: 295818 | O31: & | P31: 5143 | Q31: & | R31: 565 | S31: & | T31: - | U31: & | V31: 53 | W31: \\
B32: 2019 | C32: & | D32: 3146 | E32: & | F32: 25038 | G32: & | H32: 134 | I32: & | J32: 113 | K32: & | L32: 1102 | M32: & | N32: 348631 | O32: & | P32: 6228 | Q32: & | R32: 453 | S32: & | T32: 99 | U32: & | V32: 445 | W32: \\
B33: 2020 | C33: & | D33: 10749 | E33: & | F33: 32204 | G33: & | H33: 128 | I33: & | J33: 102 | K33: & | L33: 3861 | M33: & | N33: 343625 | O33: & | P33: 40005 | Q33: & | R33: 479 | S33: & | T33: 1 | U33: & | V33: 522 | W33: \\
B34: 2021 | C34: & | D34: 8417 | E34: & | F34: 13852 | G34: & | H34: 145 | I34: & | J34: 131 | K34: & | L34: 1708 | M34: & | N34: 546472 | O34: & | P34: 4668 | Q34: & | R34: 52 | S34: & | T34: - | U34: & | V34: 115 | W34: \\
B35: 2022 | C35: & | D35: 4758 | E35: & | F35: 6415 | G35: & | H35: 170 | I35: & | J35: 156 | K35: & | L35: 1708 | M35: & | N35: 242375 | O35: & | P35: 1952 | Q35: & | R35: 311 | S35: & | T35: 59 | U35: & | V35: 88 | W35: \\
B36: 2023 | C36: & | D36: 11978 | E36: & | F36: 11750 | G36: & | H36: 84 | I36: & | J36: 67 | K36: & | L36: 3087 | M36: & | N36: 112445 | O36: & | P36: 4100 | Q36: & | R36: 54 | S36: & | T36: - | U36: & | V36: 132 | W36: \\
B37: \hline

Sheet bsaiatf_data_2024
A1: Data for BSAI Arrowtooth Flounder
A3: biomass
A4: ebs shelf bottom trawl survey
A5: year | B5: 1992 | C5: 1993 | D5: 1994 | E5: 1995 | F5: 1996 | G5: 1997 | H5: 1998 | I5: 1999 | J5: 2000 | K5: 2001 | L5: 2002 | M5: 2003 | N5: 2004 | O5: 2005 | P5: 2006 | Q5: 2007 | R5: 2008 | S5: 2009 | T5: 2010 | U5: 2011 | V5: 2012 | W5: 2013 | X5: 2014 | Y5: 2015 | Z5: 2016 | AA5: 2017 | AB5: 2018 | AC5: 2019 | AD5: 2021 | AE5: 2022 | AF5: 2023 | AG5: 2024
A6: biomass_mt | B6: 342757.85 | C6: 444329.79 | D6: 473657.15 | E6: 445070.8 | F6: 524048.48 | G6: 459633.07 | H6: 343423 | I6: 237387.88 | J6: 312690.96 | K6: 375950.08 | L6: 311321.37 | M6: 496522.93 | N6: 516845.16 | O6: 660314.84 | P6: 604950.92 | Q6: 479427.96 | R6: 526836.33 | S6: 403584.94 | T6: 525731.52 | U6: 519361.12 | V6: 400282.25 | W6: 402452.91 | X6: 463304.54 | Y6: 407519.29 | Z6: 473808.71 | AA6: 422367.61 | AB6: 509637.55 | AC6: 576230.04 | AD6: 457568.94 | AE6: 521614.67 | AF6: 462575.05 | AG6: 582468.89
A7: biomass_var | B7: 2333827202 | C7: 1783069599 | D7: 2160538855 | E7: 4235058673 | F7: 3075168719 | G7: 3528132679 | H7: 1546588417 | I7: 3772404082 | J7: 2825435475 | K7: 1239733380 | L7: 8.7603905e+08 | M7: 1853732979 | N7: 1452861622 | O7: 2213078343 | P7: 2159115435 | Q7: 1411402356 | R7: 2101199876 | S7: 1618888745 | T7: 1940696224 | U7: 1599679202 | V7: 1842786139 | W7: 1284682990 | X7: 1031610449 | Y7: 6.3145242e+08 | Z7: 5.2802361e+08 | AA7: 7.6560258e+08 | AB7: 1240718258 | AC7: 1461613923 | AD7: 1483649577 | AE7: 3735622656 | AF7: 1508023988 | AG7: 3065091650
A9: ai bottom trawl survey
A10: year | B10: 1994 | C10: 1997 | D10: 2000 | E10: 2002 | F10: 2004 | G10: 2006 | H10: 2010 | I10: 2012 | J10: 2014 | K10: 2016 | L10: 2018 | M10: 2022 | N10: 2024
A11: biomass_mt | B11: 58229.436 | C11: 74085.214 | D11: 65028.119 | E11: 88808.486 | F11: 95040.975 | G11: 181062.49 | H11: 80049.293 | I11: 60371.062 | J11: 75957.574 | K11: 65900.419 | L11: 59492.998 | M11: 58008.174 | N11: 45219.398
A12: biomass_var | B12: 68376681 | C12: 69010171 | D12: 52540980 | E12: 1.4029581e+08 | F12: 1.5294561e+08 | G12: 2419833506 | H12: 2.378217e+08 | I12: 102366725 | J12: 1.2221661e+08 | K12: 1.7080229e+08 | L12: 48564795 | M12: 49844462 | N12: 52586951
A14: ebs slope bottom trawl survey
A15: year | B15: 2002 | C15: 2004 | D15: 2008 | E15: 2010 | F15: 2012 | G15: 2016
A16: biomass_mt | B16: 42998.819 | C16: 53820.817 | D16: 68612.394 | E16: 75979.308 | F16: 73128.598 | G16: 45581.888
A17: biomass_var | B17: 31447236 | C17: 33074420 | D17: 77916883 | E17: 1.2688745e+08 | F17: 171498524 | G17: 28991328
A19: age bins | B19: 1 | C19: 2 | D19: 3 | E19: 4 | F19: 5 | G19: 6 | H19: 7 | I19: 8 | J19: 9 | K19: 10 | L19: 11 | M19: 12 | N19: 13 | O19: 14 | P19: 15 | Q19: 16 | R19: 17 | S19: 18 | T19: 19 | U19: 20 | V19: 21+
A21: ebs shelf bottom trawl survey age compositions
A22: female
A23: 1993 | B23: 0 | C23: 0 | D23: 10408082 | E23: 34816588 | F23: 50618673 | G23: 121792277 | H23: 99982654 | I23: 75901048 | J23: 28284438 | K23: 20362577 | L23: 633502 | M23: 502179 | N23: 103467 | O23: 0 | P23: 0 | Q23: 0 | R23: 0 | S23: 0 | T23: 0 | U23: 0 | V23: 0
A24: 1994 | B24: 0 | C24: 2811177 | D24: 29290554 | E24: 11834230 | F24: 99543012 | G24: 106324768 | H24: 70688636 | I24: 44101188 | J24: 32365295 | K24: 13113474 | L24: 1241369 | M24: 0 | N24: 0 | O24: 0 | P24: 0 | Q24: 0 | R24: 0 | S24: 0 | T24: 0 | U24: 0 | V24: 0
A25: 1996 | B25: 1954092 | C25: 16317352 | D25: 54657137 | E25: 53006458 | F25: 50867502 | G25: 42242130 | H25: 34691140 | I25: 52086766 | J25: 59252144 | K25: 50581612 | L25: 23779956 | M25: 7383216 | N25: 3679056 | O25: 0 | P25: 0 | Q25: 0 | R25: 0 | S25: 0 | T25: 0 | U25: 0 | V25: 0
A26: 1998 | B26: 2726344 | C26: 28639563 | D26: 67791637 | E26: 72783702 | F26: 55723445 | G26: 27960604 | H26: 36507793 | I26: 26739826 | J26: 21986857 | K26: 14056648 | L26: 8678940 | M26: 6591358 | N26: 382881 | O26: 0 | P26: 0 | Q26: 0 | R26: 0 | S26: 0 | T26: 0 | U26: 0 | V26: 0
A27: 2004 | B27: 8721813 | C27: 139399509 | D27: 189833569 | E27: 158167334 | F27: 143018256 | G27: 65719903 | H27: 31428010 | I27: 30848578 | J27: 19865282 | K27: 7708618 | L27: 5661570 | M27: 6897639 | N27: 342570 | O27: 351078 | P27: 241184 | Q27: 1581682 | R27: 0 | S27: 0 | T27: 0 | U27: 0 | V27: 0
A28: 2010 | B28: 371290 | C28: 81531113 | D28: 84925964 | E28: 147685024 | F28: 200798241 | G28: 98699381 | H28: 94570373 | I28: 23418874 | J28: 21563028 | K28: 9388419 | L28: 5664541 | M28: 2256971 | N28: 2130523 | O28: 334859 | P28: 849834 | Q28: 1522920 | R28: 0 | S28: 0 | T28: 554609 | U28: 141471 | V28: 766548
A29: 2012 | B29: 121847 | C29: 30998345 | D29: 77153141 | E29: 94193395 | F29: 93590081 | G29: 114083646 | H29: 71678254 | I29: 34204372 | J29: 41059099 | K29: 10909168 | L29: 6915354 | M29: 1825075 | N29: 1192752 | O29: 758328 | P29: 0 | Q29: 1019918 | R29: 252405 | S29: 73225 | T29: 0 | U29: 0 | V29: 72286
A30: 2014 | B30: 2803545 | C30: 51645429 | D30: 74009755 | E30: 58135092 | F30: 73553151 | G30: 71205233 | H30: 63615331 | I30: 32270441 | J30: 32143215 | K30: 22396090 | L30: 14498176 | M30: 9834462 | N30: 1053664 | O30: 959602 | P30: 491891 | Q30: 807334 | R30: 130916 | S30: 0 | T30: 0 | U30: 167349 | V30: 424849
A31: 2015 | B31: 0 | C31: 23871929 | D31: 60906325 | E31: 64855924 | F31: 56664125 | G31: 73496403 | H31: 60185742 | I31: 32045213 | J31: 28761447 | K31: 20554257 | L31: 19288508 | M31: 7709927 | N31: 3503393 | O31: 5694528 | P31: 1909437 | Q31: 799785 | R31: 346190 | S31: 0 | T31: 190891 | U31: 0 | V31: 455759
A32: 2016 | B32: 0 | C32: 26315412 | D32: 112468933 | E32: 154817447 | F32: 92846813 | G32: 63756251 | H32: 37043749 | I32: 25229122 | J32: 21526776 | K32: 17565112 | L32: 12425529 | M32: 9543354 | N32: 7854407 | O32: 1002524 | P32: 1812494 | Q32: 0 | R32: 0 | S32: 587562 | T32: 0 | U32: 0 | V32: 0
A33: 2017 | B33: 0 | C33: 51121662 | D33: 52865902 | E33: 133962903 | F33: 100342915 | G33: 43494155 | H33: 27325731 | I33: 19273345 | J33: 17593822 | K33: 18711238 | L33: 15165662 | M33: 6355199 | N33: 4459482 | O33: 1724409 | P33: 718125 | Q33: 0 | R33: 0 | S33: 805878 | T33: 0 | U33: 0 | V33: 0
A34: 2018 | B34: 0 | C34: 161745800 | D34: 123351252 | E34: 103789903 | F34: 131277695 | G34: 101799490 | H34: 46656208 | I34: 17889828 | J34: 17870185 | K34: 13025136 | L34: 7082536 | M34: 7259786 | N34: 5081933 | O34: 912598 | P34: 0 | Q34: 0 | R34: 1093447 | S34: 0 | T34: 0 | U34: 0 | V34: 0
... A36: 2021 | B36: 0 | C36: 0 | D36: 161656676 | E36: 120269392 | F36: 162207014 | G36: 47880275 | H36: 32452492 | I36: 19464395 | J36: 7283789 | K36: 1458800 | L36: 2225073 | M36: 3359279 | N36: 2834920 | O36: 1424079 | P36: 2097660 | Q36: 798736 | R36: 409607 | S36: 0 | T36: 0 | U36: 0 | V36: 0
A38: male
A39: 1993 | B39: 0 | C39: 0 | D39: 16763705 | E39: 6830736 | F39: 61012558 | G39: 56619519 | H39: 31019536 | I39: 8976840 | J39: 1319594 | K39: 450707 | L39: 0 | M39: 0 | N39: 0 | O39: 0 | P39: 0 | Q39: 0 | R39: 0 | S39: 0 | T39: 0 | U39: 0 | V39: 0
A40: 1994 | B40: 0 | C40: 12865734 | D40: 13407040 | E40: 17215009 | F40: 29553581 | G40: 42654480 | H40: 17475468 | I40: 31648622 | J40: 0 | K40: 2344501 | L40: 0 | M40: 0 | N40: 0 | O40: 0 | P40: 0 | Q40: 0 | R40: 0 | S40: 0 | T40: 0 | U40: 0 | V40: 0
A41: 1996 | B41: 0 | C41: 6355624 | D41: 19618750 | E41: 12870309 | F41: 33065806 | G41: 22577996 | H41: 9645638 | I41: 22278889 | J41: 3094048 | K41: 6178786 | L41: 0 | M41: 231769 | N41: 0 | O41: 0 | P41: 0 | Q41: 0 | R41: 0 | S41: 0 | T41: 0 | U41: 0 | V41: 0
A42: 1998 | B42: 0 | C42: 12663574 | D42: 49842818 | E42: 29270487 | F42: 16201686 | G42: 5348072 | H42: 11856460 | I42: 2747428 | J42: 0 | K42: 2609596 | L42: 0 | M42: 0 | N42: 0 | O42: 0 | P42: 0 | Q42: 0 | R42: 0 | S42: 0 | T42: 0 | U42: 0 | V42: 0
A43: 2004 | B43: 7599173 | C43: 99290331 | D43: 89021729 | E43: 73991763 | F43: 38729973 | G43: 24316339 | H43: 9076550 | I43: 7047346 | J43: 1454632 | K43: 0 | L43: 112914 | M43: 0 | N43: 0 | O43: 0 | P43: 0 | Q43: 0 | R43: 506768 | S43: 0 | T43: 0 | U43: 0 | V43: 0
A44: 2010 | B44: 222339 | C44: 43295449 | D44: 43345415 | E44: 54067360 | F44: 62734935 | G44: 30387639 | H44: 26757935 | I44: 5052087 | J44: 1713378 | K44: 722498 | L44: 0 | M44: 0 | N44: 0 | O44: 0 | P44: 0 | Q44: 0 | R44: 0 | S44: 0 | T44: 0 | U44: 0 | V44: 0
A45: 2012 | B45: 0 | C45: 18035547 | D45: 44679488 | E45: 59651089 | F45: 33796916 | G45: 32141880 | H45: 11858902 | I45: 6657820 | J45: 5863968 | K45: 411944 | L45: 1248738 | M45: 536040 | N45: 0 | O45: 0 | P45: 0 | Q45: 0 | R45: 0 | S45: 0 | T45: 0 | U45: 0 | V45: 0
A46: 2014 | B46: 99853 | C46: 23618785 | D46: 23595000 | E46: 41361876 | F46: 35571045 | G46: 29000365 | H46: 12357338 | I46: 2563104 | J46: 4156254 | K46: 2894977 | L46: 0 | M46: 0 | N46: 0 | O46: 0 | P46: 0 | Q46: 0 | R46: 0 | S46: 0 | T46: 0 | U46: 0 | V46: 0
A47: 2015 | B47: 0 | C47: 12428840 | D47: 25171270 | E47: 25109310 | F47: 31040977 | G47: 19444856 | H47: 12801311 | I47: 8255032 | J47: 3879499 | K47: 1784202 | L47: 2364919 | M47: 1389851 | N47: 256229 | O47: 798957 | P47: 0 | Q47: 0 | R47: 0 | S47: 0 | T47: 0 | U47: 0 | V47: 0
...

Sheet CEATTLE
B1: #================================================================================
B2: # | C2: DATA | D2: BELOW | E2: for | F2: 2023 | G2: runs
B3: #================================================================================
B4: #
B5: #nages | C5: : | D5: number | E5: of | F5: age | G5: groups | H5: UPDATED
B6: ##__________________________________________________________
B7: 12 | C7: 12 | D7: 21
B8: #
B9: #
B10: #==============================================================================
B11: #
B12: ##<<<<<<<<------------ | C12: CATCH | D12: DATA | E12: ----------------->>>>>>>>
B13: #
B14: #==============================================================================
B15: #
B16: #
B17: ##__________________________________________________________
B18: #nyrs_tc_biom | C18: : | D18: number | E18: of | F18: catch | G18: biomass | H18: index | I18: years
B19: ##__________________________________________________________
A20: 1 | B20: 46 | C20: 46 | D20: 46
B21: ##__________________________________________________________
B22: #yrs_tc_biom | C22: : | D22: catch | E22: biomass | F22: years
B23: ##__________________________________________________________
B24: 1979 | C24: 1980 | D24: 1981 | E24: 1982 | F24: 1983 | G24: 1984 | H24: 1985 | I24: 1986 | J24: 1987 | K24: 1988 | L24: 1989 | M24: 1990 | N24: 1991 | O24: 1992 | P24: 1993 | Q24: 1994 | R24: 1995 | S24: 1996 | T24: 1997 | U24: 1998 | V24: 1999 | W24: 2000 | X24: 2001 | Y24: 2002 | Z24: 2003 | AA24: 2004 | AB24: 2005 | AC24: 2006 | AD24: 2007 | AE24: 2008 | AF24: 2009 | AG24: 2010 | AH24: 2011 | AI24: 2012 | AJ24: 2013 | AK24: 2014 | AL24: 2015 | AM24: 2016 | AN24: 2017 | AO24: 2018 | AP24: 2019 | AQ24: 2020 | AR24: 2021 | AS24: 2022 | AT24: 2023 | AU24: 2024
B25: 1979 | C25: 1980 | D25: 1981 | E25: 1982 | F25: 1983 | G25: 1984 | H25: 1985 | I25: 1986 | J25: 1987 | K25: 1988 | L25: 1989 | M25: 1990 | N25: 1991 | O25: 1992 | P25: 1993 | Q25: 1994 | R25: 1995 | S25: 1996 | T25: 1997 | U25: 1998 | V25: 1999 | W25: 2000 | X25: 2001 | Y25: 2002 | Z25: 2003 | AA25: 2004 | AB25: 2005 | AC25: 2006 | AD25: 2007 | AE25: 2008 | AF25: 2009 | AG25: 2010 | AH25: 2011 | AI25: 2012 | AJ25: 2013 | AK25: 2014 | AL25: 2015 | AM25: 2016 | AN25: 2017 | AO25: 2018 | AP25: 2019 | AQ25: 2020 | AR25: 2021 | AS25: 2022 | AT25: 2023 | AU25: 2024
B26: 1979 | C26: 1980 | D26: 1981 | E26: 1982 | F26: 1983 | G26: 1984 | H26: 1985 | I26: 1986 | J26: 1987 | K26: 1988 | L26: 1989 | M26: 1990 | N26: 1991 | O26: 1992 | P26: 1993 | Q26: 1994 | R26: 1995 | S26: 1996 | T26: 1997 | U26: 1998 | V26: 1999 | W26: 2000 | X26: 2001 | Y26: 2002 | Z26: 2003 | AA26: 2004 | AB26: 2005 | AC26: 2006 | AD26: 2007 | AE26: 2008 | AF26: 2009 | AG26: 2010 | AH26: 2011 | AI26: 2012 | AJ26: 2013 | AK26: 2014 | AL26: 2015 | AM26: 2016 | AN26: 2017 | AO26: 2018 | AP26: 2019 | AQ26: 2020 | AR26: 2021 | AS26: 2022 | AT26: 2023 | AU26: 2024
B27: ##__________________________________________________________
B28: #tcb_biom_obs | C28: : | D28: Catch | E28: biomass | F28: 1000
B29: ##__________________________________________________________
B30: # | C30: Pollock
A31: =COUNT(B31:BT31) -> 46 | B31: ='pm_24.dat '!Q143*1000 -> 935714 | C31: ='pm_24.dat '!R143*1000 -> 958280 | D31: ='pm_24.dat '!S143*1000 -> 973502 | E31: ='pm_24.dat '!T143*1000 -> 955964 | F31: ='pm_24.dat '!U143*1000 -> 981450 | G31: ='pm_24.dat '!V143*1000 -> 1092055 | H31: ='pm_24.dat '!W143*1000 -> 1139676 | I31: ='pm_24.dat '!X143*1000 -> 1141993 | ... AU31: ='pm_24.dat '!BJ143*1000 -> 1300000
B32: # | C32: Cod
A33: =COUNT(B33:BT33) -> 46 | B33: 33761 | C33: 35058 | D33: 56507 | E33: 61104 | F33: 94801 | G33: 125103 | H33: 143447 | I33: 135605 | J33: 149903 | K33: 203071 | L33: 178323 | M33: 172067 | N33: 210241 | O33: 164210 | P33: 133186 | Q33: 172263 | R33: 228498 | S33: 209067 | T33: 232601 | U33: 158529 | V33: 145867 | W33: 151376 | X33: 142542 | Y33: 166555 | Z33: 175443 | AA33: 183748 | AB33: 182940 | AC33: 168818 | AD33: 140129 | AE33: 139802 | AF33: 147174 | AG33: 142844 | AH33: 209201 | AI33: 232623 | AJ33: 236691 | AK33: 238718 | AL33: 232829 | AM33: 247620 | AN33: 237851 | AO33: 199867 | AP33: 178904 | AQ33: 155665 | AR33: 121749 | AS33: 148810 | AT33: 143541 | AU33: 165659
B34: # | C34: ATF
A35: =COUNT(B35:BT35) -> 46 | B35: =bsaiatf_data_2024!D190 -> 12921.3 | C35: =bsaiatf_data_2024!E190 -> 16527.6 | D35: =bsaiatf_data_2024!F190 -> 15401.7 | E35: =bsaiatf_data_2024!G190 -> 10366.2 | F35: =bsaiatf_data_2024!H190 -> 12572.1 | G35: =bsaiatf_data_2024!I190 -> 8506.8 | H35: =bsaiatf_data_2024!J190 -> 6702.3 | I35: =bsaiatf_data_2024!K190 -> 6462.9 | ... AU35: =bsaiatf_data_2024!AW190 -> 7013.9388
B36: #INGRID'snote(51) | C36: fishery | D36: catch | E36: 1979-2014 | F36: (with | G36: Kamchatka | H36: subtracted) | I36: (updated | J36: yrs | K36: back | L36: thru | M36: 2006 | N36: Oct | O36: 7 | P36: 2014 | Q36: used | R36: last | S36: yrs | T36: catchfor | U36: this | V36: yrs | W36: estimate) | X36: put | Y36: in | Z36: new | AA36: data | AB36: from | AC36: Table6.1
B37: ##__________________________________________________________
B38: #nyrs_fsh_comp | C38: : | D38: N | E38: age/size | F38: observations | G38: by | H38: spp
B39: ##__________________________________________________________
B40: =COUNT(B44:BD44) -> 45 | C40: 45 | D40: 45
...

Sheet bts_wt_age biom table
B1: 1982 | C1: 1983 | D1: 1984 | E1: 1985 | F1: 1986 | G1: 1987 | H1: 1988 | I1: 1989 | J1: 1990 | K1: 1991 | L1: 1992 | M1: 1993 | N1: 1994 | O1: 1995 | P1: 1996 | Q1: 1997 | R1: 1998 | S1: 1999 | T1: 2000 | U1: 2001 | V1: 2002 | W1: 2003 | X1: 2004 | Y1: 2005 | Z1: 2006 | AA1: 2007 | AB1: 2008 | AC1: 2009 | AD1: 2010 | AE1: 2011 | AF1: 2012 | AG1: 2013 | AH1: 2014 | AI1: 2015 | AJ1: 2016 | AK1: 2017 | AL1: 2018 | AM1: 2019 | AN1: 2020 | AO1: 2021 | AP1: 2022 | AQ1: 2023 | AR1: 2024
A2: 1 | B2: 0.026205768 | C2: 0.016466601 | D2: 0.016306697 | E2: 0.017032291 | F2: 0.012679101 | G2: 0.025633854 | H2: 0.016132698 | I2: 0.018833545 | J2: 0.014413264 | K2: 0.020605993 | L2: 0.016772385 | M2: 0.012209558 | N2: 0.017732801 | O2: 0.017411934 | P2: 0.018715707 | Q2: 0.015412472 | R2: 0.014883778 | S2: 0.013097441 | T2: 0.01163705 | U2: 0.014819032 | V2: 0.012825707 | W2: 0.021351905 | X2: 0.019468921 | Y2: 0.020195643 | Z2: 0.0093771808 | AA2: 0.012513048 | AB2: 0.012618844 | AC2: 0.011047579 | AD2: 0.017537099 | AE2: 0.014907673 | AF2: 0.013099156 | AG2: 0.015229169 | AH2: 0.01660691 | AI2: 0.017457807 | AJ2: 0.021930009 | AK2: 0.020955314 | AL2: 0.022427235 | AM2: 0.021557386 | AN2: NA | AO2: 0.022498681 | AP2: 0.017285352 | AQ2: 0.016290283 | AR2: 0.017541583
A3: 2 | B3: 0.077368661 | C3: 0.10462804 | D3: 0.067560013 | E3: 0.082113337 | F3: 0.062722585 | G3: 0.10646168 | H3: 0.095171865 | I3: 0.08966227 | J3: 0.17105639 | K3: 0.13638904 | L3: 0.12973221 | M3: 0.10251026 | N3: 0.089098398 | O3: 0.063233781 | P3: 0.080421813 | Q3: 0.083028837 | R3: 0.076274765 | S3: 0.090593728 | T3: 0.090123893 | U3: 0.075871477 | V3: 0.093839211 | W3: 0.11382482 | X3: 0.10359455 | Y3: 0.10749329 | Z3: 0.099581012 | AA3: 0.10292719 | AB3: 0.060552625 | AC3: 0.066319807 | AD3: 0.084274743 | AE3: 0.082344511 | AF3: 0.079277365 | AG3: 0.080877861 | AH3: 0.11396832 | AI3: 0.087281454 | AJ3: 0.08192566 | AK3: 0.10407452 | AL3: 0.095396352 | AM3: 0.1133557 | AN3: NA | AO3: 0.10247386 | AP3: 0.11726235 | AQ3: 0.11730159 | AR3: 0.094822856
A4: 3 | B4: 0.17984088 | C4: 0.18543452 | D4: 0.19641513 | E4: 0.21258432 | F4: 0.14505392 | G4: 0.24569976 | H4: 0.27475098 | I4: 0.16816857 | J4: 0.18121031 | K4: 0.19937224 | L4: 0.29996991 | M4: 0.28949641 | N4: 0.22785764 | O4: 0.1453353 | P4: 0.15087054 | Q4: 0.20099867 | R4: 0.19454517 | S4: 0.2055833 | T4: 0.2314951 | U4: 0.18016288 | V4: 0.25933848 | W4: 0.28777277 | X4: 0.28146998 | Y4: 0.23754159 | Z4: 0.18948028 | AA4: 0.28960623 | AB4: 0.25535378 | AC4: 0.24992973 | AD4: 0.266088 | AE4: 0.22974241 | AF4: 0.20164657 | AG4: 0.21232816 | AH4: 0.25779955 | AI4: 0.33240677 | AJ4: 0.2988499 | AK4: 0.25368745 | AL4: 0.22572931 | AM4: 0.29701389 | AN4: NA | AO4: 0.23874587 | AP4: 0.26733573 | AQ4: 0.2713962 | AR4: 0.32923136
A5: 4 | B5: 0.36696323 | C5: 0.36118307 | D5: 0.3066841 | E5: 0.33632738 | F5: 0.32711326 | G5: 0.2938431 | H5: 0.32317442 | I5: 0.3052703 | J5: 0.35206067 | K5: 0.35376235 | L5: 0.40907179 | M5: 0.46988783 | N5: 0.41442535 | O5: 0.33988342 | P5: 0.2996725 | Q5: 0.3000881 | R5: 0.31556663 | S5: 0.36341935 | T5: 0.43161498 | U5: 0.37537758 | V5: 0.38673792 | W5: 0.4509592 | X5: 0.44964078 | Y5: 0.41234005 | Z5: 0.43836275 | AA5: 0.51464886 | AB5: 0.4739998 | AC5: 0.50350272 | AD5: 0.51878576 | AE5: 0.51185188 | AF5: 0.42138328 | AG5: 0.50512228 | AH5: 0.4508754 | AI5: 0.44892155 | AJ5: 0.53027141 | AK5: 0.47203782 | AL5: 0.43454262 | AM5: 0.50094768 | AN5: NA | AO5: 0.44695999 | AP5: 0.44318865 | AQ5: 0.41687565 | AR5: 0.47575692
A6: 5 | B6: 0.54007477 | C6: 0.52095706 | D6: 0.48488267 | E6: 0.47324341 | F6: 0.41958098 | G6: 0.42630492 | H6: 0.42643289 | I6: 0.39071365 | J6: 0.43324723 | K6: 0.56350199 | L6: 0.50467969 | M6: 0.52522104 | N6: 0.57280505 | O6: 0.48033316 | P6: 0.50891045 | Q6: 0.36966814 | R6: 0.45714747 | S6: 0.4199386 | T6: 0.47182515 | U6: 0.54885313 | V6: 0.53331987 | W6: 0.64469695 | X6: 0.59186643 | Y6: 0.55378122 | Z6: 0.61177803 | AA6: 0.63919194 | AB6: 0.61003273 | AC6: 0.69671087 | AD6: 0.69009797 | AE6: 0.66165794 | AF6: 0.61116787 | AG6: 0.58176434 | AH6: 0.58217254 | AI6: 0.59033473 | AJ6: 0.60493638 | AK6: 0.63360879 | AL6: 0.59955499 | AM6: 0.63674065 | AN6: NA | AO6: 0.58457981 | AP6: 0.59097485 | AQ6: 0.53343194 | AR6: 0.57828802
A7: 6 | B7: 0.89063094 | C7: 0.71594416 | D7: 0.59752616 | E7: 0.68096711 | F7: 0.61127764 | G7: 0.52330365 | H7: 0.50128528 | I7: 0.5050153 | J7: 0.5450222 | K7: 0.6379421 | L7: 0.58947543 | M7: 0.64543159 | N7: 0.70886324 | O7: 0.65684408 | P7: 0.63350346 | Q7: 0.606303 | R7: 0.52549741 | S7: 0.57229012 | T7: 0.5667108 | U7: 0.69227147 | V7: 0.67867991 | W7: 0.75425557 | X7: 0.72534733 | Y7: 0.66987158 | Z7: 0.68941212 | AA7: 0.80280689 | AB7: 0.74239033 | AC7: 0.79058751 | AD7: 0.88848653 | AE7: 0.77502012 | AF7: 0.77438196 | AG7: 0.73618254 | AH7: 0.72889452 | AI7: 0.68935601 | AJ7: 0.70050391 | AK7: 0.67283381 | AL7: 0.69586606 | AM7: 0.74142539 | AN7: NA | AO7: 0.71277143 | AP7: 0.70946782 | AQ7: 0.66030587 | AR7: 0.61925246
A8: 7 | B8: 1.2037654 | C8: 1.0203394 | D8: 0.93047187 | E8: 0.89133258 | F8: 0.81913046 | G8: 0.69169736 | H8: 0.66056901 | I8: 0.71004224 | J8: 0.6225819 | K8: 0.72004131 | L8: 0.77752687 | M8: 0.73919061 | N8: 0.7468426 | O8: 0.68022791 | P8: 0.78004482 | Q8: 0.74987458 | R8: 0.84027327 | S8: 0.68535041 | T8: 0.70561069 | U8: 0.80503042 | V8: 0.74603497 | W8: 0.83725454 | X8: 0.84710008 | Y8: 0.84306257 | Z8: 0.82408302 | AA8: 0.9053002 | AB8: 0.86404742 | AC8: 0.99411663 | AD8: 1.0839435 | AE8: 0.9243594 | AF8: 0.92079347 | AG8: 0.97732284 | AH8: 0.80253578 | AI8: 0.79507287 | AJ8: 0.77865003 | AK8: 0.75734475 | AL8: 0.77650392 | AM8: 0.83064097 | AN8: NA | AO8: 0.80419877 | AP8: 0.78059251 | AQ8: 0.80251332 | AR8: 0.70358279
A9: 8 | B9: 1.364783 | C9: 1.3065892 | D9: 1.3781208 | E9: 1.2315979 | F9: 1.0295669 | G9: 0.8256326 | H9: 0.87735348 | I9: 0.80356768 | J9: 0.76155811 | K9: 0.81701103 | L9: 0.86999925 | M9: 0.8663609 | N9: 1.0865222 | O9: 0.89685029 | P9: 0.87126711 | Q9: 0.86803151 | R9: 0.93873483 | S9: 0.8997229 | T9: 0.79994726 | U9: 0.87329105 | V9: 0.92029674 | W9: 0.96355008 | X9: 0.96588869 | Y9: 0.95761748 | Z9: 0.90074247 | AA9: 1.0275735 | AB9: 0.99537623 | AC9: 1.107127 | AD9: 1.1810656 | AE9: 1.0967371 | AF9: 1.1325587 | AG9: 1.1637561 | AH9: 1.1136074 | AI9: 0.92242361 | AJ9: 0.83573939 | AK9: 0.82078781 | AL9: 0.82630539 | AM9: 0.94639468 | AN9: NA | AO9: 0.85590952 | AP9: 0.88119506 | AQ9: 0.93535797 | AR9: 0.94511421
A10: 9 | B10: 1.5027682 | C10: 1.5105197 | D10: 1.5135626 | E10: 1.6494576 | F10: 1.3097433 | G10: 0.97431407 | H10: 0.8901678 | I10: 1.0999788 | J10: 0.89588118 | K10: 0.98209054 | L10: 0.97166959 | M10: 1.0621986 | N10: 1.3033178 | O10: 1.0749126 | P10: 1.0274454 | Q10: 1.1443025 | R10: 1.0123137 | S10: 1.1090659 | T10: 0.94677266 | U10: 0.95773301 | V10: 1.0333868 | W10: 1.0391813 | X10: 1.0764127 | Y10: 1.0186008 | Z10: 1.0494042 | AA10: 1.1223743 | AB10: 1.0655211 | AC10: 1.1793418 | AD10: 1.2236275 | AE10: 1.2319079 | AF10: 1.3091591 | AG10: 1.3240097 | AH10: 1.2459001 | AI10: 1.2163205 | AJ10: 0.94074927 | AK10: 0.90365743 | AL10: 0.93655477 | AM10: 0.95985969 | AN10: NA | AO10: 0.98023943 | AP10: 0.97573352 | AQ10: 0.96296479 | AR10: 1.0050599
A11: 10 | B11: 1.6698665 | C11: 1.5784693 | D11: 1.7310354 | E11: 1.6080991 | F11: 1.6253411 | G11: 1.180509 | H11: 1.1079468 | I11: 1.0887268 | J11: 1.1052711 | K11: 1.0800511 | L11: 1.080256 | M11: 1.0990736 | N11: 1.2357686 | O11: 1.3630232 | P11: 1.1666849 | Q11: 1.2174555 | R11: 1.0868388 | S11: 1.1608222 | T11: 1.1941958 | U11: 1.0988387 | V11: 1.1270085 | W11: 1.2105844 | X11: 1.1468187 | Y11: 1.0822203 | Z11: 1.1771019 | AA11: 1.3919689 | AB11: 1.1997013 | AC11: 1.4432049 | AD11: 1.3106357 | AE11: 1.2770545 | AF11: 1.3793823 | AG11: 1.4148139 | AH11: 1.4623503 | AI11: 1.2428098 | AJ11: 0.99969551 | AK11: 0.92189874 | AL11: 0.95807751 | AM11: 1.0437957 | AN11: NA | AO11: 1.1501008 | AP11: 1.0701158 | AQ11: 1.0104949 | AR11: 1.0410179
A12: 11 | B12: 1.8208868 | C12: 1.6312528 | D12: 1.8698851 | E12: 1.7214547 | F12: 1.7353881 | G12: 1.4936964 | H12: 1.3440926 | I12: 1.2255464 | J12: 1.1424814 | K12: 1.3277349 | L12: 1.2259851 | M12: 1.2925776 | N12: 1.3463449 | O12: 1.3076588 | P12: 1.386758 | Q12: 1.3488556 | R12: 1.2627064 | S12: 1.3005269 | T12: 1.4278748 | U12: 1.3232088 | V12: 1.1459054 | W12: 1.2187947 | X12: 1.1919267 | Y12: 1.3357433 | Z12: 1.2602828 | AA12: 1.3485866 | AB12: 1.4778601 | AC12: 1.5245784 | AD12: 1.431439 | AE12: 1.425958 | AF12: 1.4175076 | AG12: 1.5147019 | AH12: 1.7057377 | AI12: 1.5838626 | AJ12: 1.2142131 | AK12: 1.0767442 | AL12: 1.0842715 | AM12: 1.0124746 | AN12: NA | AO12: 1.0649628 | AP12: 1.3270858 | AQ12: 1.1503332 | AR12: 1.1376507
A13: 12 | B13: 1.8721143 | C13: 1.5707959 | D13: 1.8518142 | E13: 2.0162688 | F13: 1.9396121 | G13: 1.5168686 | H13: 1.3842114 | I13: 1.3119255 | J13: 1.311178 | K13: 1.4135751 | L13: 1.4716865 | M13: 1.4077627 | N13: 1.440092 | O13: 1.4014582 | P13: 1.5029126 | Q13: 1.5321503 | R13: 1.3974489 | S13: 1.3743154 | T13: 1.469941 | U13: 1.535166 | V13: 1.4447697 | W13: 1.4005883 | X13: 1.3048036 | Y13: 1.2801052 | Z13: 1.3780133 | AA13: 1.3854663 | AB13: 1.4311636 | AC13: 1.6869991 | AD13: 1.5994659 | AE13: 1.4890254 | AF13: 1.480601 | AG13: 1.5422469 | AH13: 1.6186681 | AI13: 1.5267266 | AJ13: 1.5942525 | AK13: 1.0311737 | AL13: 0.93573701 | AM13: 1.0564222 | AN13: NA | AO13: 1.1514638 | AP13: 1.3051274 | AQ13: 1.1402658 | AR13: 1.2058032
A14: 13 | B14: 2.1519164 | C14: 1.8129217 | D14: 1.9701182 | E14: 2.1048368 | F14: 2.2206108 | G14: 1.9276495 | H14: 1.9046605 | I14: 1.2899614 | J14: 1.3755016 | K14: 1.5711976 | L14: 1.6762203 | M14: 1.6075729 | N14: 1.4919087 | O14: 1.5174323 | P14: 1.6643796 | Q14: 1.6015124 | R14: 1.5188572 | S14: 1.8227476 | T14: 1.7141411 | U14: 1.6147609 | V14: 1.6310633 | W14: 1.5918506 | X14: 1.5072477 | Y14: 1.3045111 | Z14: 1.4481496 | AA14: 1.6990055 | AB14: 1.6502071 | AC14: 1.9426008 | AD14: 1.8183168 | AE14: 1.6109203 | AF14: 1.5438559 | AG14: 1.6925614 | AH14: 1.711729 | AI14: 1.4931582 | AJ14: 1.4009801 | AK14: 1.2739006 | AL14: 1.5071627 | AM14: 1.0424254 | AN14: NA | AO14: 1.3125886 | AP14: 1.3562492 | AQ14: 1.4628117 | AR14: 1.3140829
A15: 14 | B15: 1.8248515 | C15: 1.5555355 | D15: 1.7446386 | E15: 1.8017956 | F15: 2.2816761 | G15: 2.2288837 | H15: 1.1603828 | I15: 1.2903494 | J15: 1.4868107 | K15: 1.8148823 | L15: 1.7302859 | M15: 1.6890831 | N15: 1.6707974 | O15: 1.5107963 | P15: 1.6924256 | Q15: 1.6218681 | R15: 1.8966153 | S15: 1.7903409 | T15: 1.7669192 | U15: 1.8138578 | V15: 1.7958417 | W15: 1.5283883 | X15: 1.8070748 | Y15: 1.4828079 | Z15: 1.4361417 | AA15: 1.5937535 | AB15: 1.7922242 | AC15: 2.2266515 | AD15: 2.1394781 | AE15: 1.7573364 | AF15: 1.8390102 | AG15: 1.9132571 | AH15: 1.9325002 | AI15: 1.5547109 | AJ15: 1.6820231 | AK15: 1.1479984 | AL15: NA | AM15: 1.2825423 | AN15: NA | AO15: 1.0260876 | AP15: 1.2389392 | AQ15: 1.8926323 | AR15: 1.435522
A16: 15 | B16: 2.6626429 | C16: 1.9861618 | D16: 2.124745 | E16: 2.4895723 | F16: NA | G16: 2.3730768 | H16: 1.7444947 | I16: 1.4807348 | J16: 1.777957 | K16: 1.9797202 | L16: 1.6934578 | M16: 1.8109887 | N16: 1.7429204 | O16: 1.7658965 | P16: 1.8215122 | Q16: 1.7962072 | R16: 1.9089077 | S16: 2.08579 | T16: 2.0164592 | U16: 1.9689663 | V16: 1.9792397 | W16: 1.8675554 | X16: 1.8272597 | Y16: 1.6038479 | Z16: 1.5094692 | AA16: 1.6582967 | AB16: 1.8772479 | AC16: 2.3172332 | AD16: 2.4438841 | AE16: 2.0580836 | AF16: 2.0709839 | AG16: 1.996012 | AH16: 1.9968602 | AI16: 1.8107581 | AJ16: 1.4709501 | AK16: 1.5489652 | AL16: 1.5194146 | AM16: NA | AN16: NA | AO16: 1.3824833 | AP16: 1.8623408 | AQ16: 1.5068638 | AR16: 1.7913662
A21: {=TRANSPOSE(A1:AR16)} -> 0 | B21: 1 | C21: 2 | D21: 3 | E21: 4 | F21: 5 | G21: 6 | H21: 7 | I21: 8 | J21: 9 | K21: 10 | L21: 11 | M21: 12 | N21: 13 | O21: 14 | P21: 15
A22: 1982 | B22: 0.026205768 | C22: 0.077368661 | D22: 0.17984088 | E22: 0.36696323 | F22: 0.54007477 | G22: 0.89063094 | H22: 1.2037654 | I22: 1.364783 | J22: 1.5027682 | K22: 1.6698665 | L22: 1.8208868 | M22: 1.8721143 | N22: 2.1519164 | O22: 1.8248515 | P22: 2.6626429
A23: 1983 | B23: 0.016466601 | C23: 0.10462804 | D23: 0.18543452 | E23: 0.36118307 | F23: 0.52095706 | G23: 0.71594416 | H23: 1.0203394 | I23: 1.3065892 | J23: 1.5105197 | K23: 1.5784693 | L23: 1.6312528 | M23: 1.5707959 | N23: 1.8129217 | O23: 1.5555355 | P23: 1.9861618
A24: 1984 | B24: 0.016306697 | C24: 0.067560013 | D24: 0.19641513 | E24: 0.3066841 | F24: 0.48488267 | G24: 0.59752616 | H24: 0.93047187 | I24: 1.3781208 | J24: 1.5135626 | K24: 1.7310354 | L24: 1.8698851 | M24: 1.8518142 | N24: 1.9701182 | O24: 1.7446386 | P24: 2.124745
A25: 1985 | B25: 0.017032291 | C25: 0.082113337 | D25: 0.21258432 | E25: 0.33632738 | F25: 0.47324341 | G25: 0.68096711 | H25: 0.89133258 | I25: 1.2315979 | J25: 1.6494576 | K25: 1.6080991 | L25: 1.7214547 | M25: 2.0162688 | N25: 2.1048368 | O25: 1.8017956 | P25: 2.4895723
A26: 1986 | B26: 0.012679101 | C26: 0.062722585 | D26: 0.14505392 | E26: 0.32711326 | F26: 0.41958098 | G26: 0.61127764 | H26: 0.81913046 | I26: 1.0295669 | J26: 1.3097433 | K26: 1.6253411 | L26: 1.7353881 | M26: 1.9396121 | N26: 2.2206108 | O26: 2.2816761 | P26: NA
A27: 1987 | B27: 0.025633854 | C27: 0.10646168 | D27: 0.24569976 | E27: 0.2938431 | F27: 0.42630492 | G27: 0.52330365 | H27: 0.69169736 | I27: 0.8256326 | J27: 0.97431407 | K27: 1.180509 | L27: 1.4936964 | M27: 1.5168686 | N27: 1.9276495 | O27: 2.2288837 | P27: 2.3730768
A28: 1988 | B28: 0.016132698 | C28: 0.095171865 | D28: 0.27475098 | E28: 0.32317442 | F28: 0.42643289 | G28: 0.50128528 | H28: 0.66056901 | I28: 0.87735348 | J28: 0.8901678 | K28: 1.1079468 | L28: 1.3440926 | M28: 1.3842114 | N28: 1.9046605 | O28: 1.1603828 | P28: 1.7444947
A29: 1989 | B29: 0.018833545 | C29: 0.08966227 | D29: 0.16816857 | E29: 0.3052703 | F29: 0.39071365 | G29: 0.5050153 | H29: 0.71004224 | I29: 0.80356768 | J29: 1.0999788 | K29: 1.0887268 | L29: 1.2255464 | M29: 1.3119255 | N29: 1.2899614 | O29: 1.2903494 | P29: 1.4807348
A30: 1990 | B30: 0.014413264 | C30: 0.17105639 | D30: 0.18121031 | E30: 0.35206067 | F30: 0.43324723 | G30: 0.5450222 | H30: 0.6225819 | I30: 0.76155811 | J30: 0.89588118 | K30: 1.1052711 | L30: 1.1424814 | M30: 1.311178 | N30: 1.3755016 | O30: 1.4868107 | P30: 1.777957
A31: 1991 | B31: 0.020605993 | C31: 0.13638904 | D31: 0.19937224 | E31: 0.35376235 | F31: 0.56350199 | G31: 0.6379421 | H31: 0.72004131 | I31: 0.81701103 | J31: 0.98209054 | K31: 1.0800511 | L31: 1.3277349 | M31: 1.4135751 | N31: 1.5711976 | O31: 1.8148823 | P31: 1.9797202
A32: 1992 | B32: 0.016772385 | C32: 0.12973221 | D32: 0.29996991 | E32: 0.40907179 | F32: 0.50467969 | G32: 0.58947543 | H32: 0.77752687 | I32: 0.86999925 | J32: 0.97166959 | K32: 1.080256 | L32: 1.2259851 | M32: 1.4716865 | N32: 1.6762203 | O32: 1.7302859 | P32: 1.6934578
A33: 1993 | B33: 0.012209558 | C33: 0.10251026 | D33: 0.28949641 | E33: 0.46988783 | F33: 0.52522104 | G33: 0.64543159 | H33: 0.73919061 | I33: 0.8663609 | J33: 1.0621986 | K33: 1.0990736 | L33: 1.2925776 | M33: 1.4077627 | N33: 1.6075729 | O33: 1.6890831 | P33: 1.8109887
A34: 1994 | B34: 0.017732801 | C34: 0.089098398 | D34: 0.22785764 | E34: 0.41442535 | F34: 0.57280505 | G34: 0.70886324 | H34: 0.7468426 | I34: 1.0865222 | J34: 1.3033178 | K34: 1.2357686 | L34: 1.3463449 | M34: 1.440092 | N34: 1.4919087 | O34: 1.6707974 | P34: 1.7429204
A35: 1995 | B35: 0.017411934 | C35: 0.063233781 | D35: 0.1453353 | E35: 0.33988342 | F35: 0.48033316 | G35: 0.65684408 | H35: 0.68022791 | I35: 0.89685029 | J35: 1.0749126 | K35: 1.3630232 | L35: 1.3076588 | M35: 1.4014582 | N35: 1.5174323 | O35: 1.5107963 | P35: 1.7658965
A36: 1996 | B36: 0.018715707 | C36: 0.080421813 | D36: 0.15087054 | E36: 0.2996725 | F36: 0.50891045 | G36: 0.63350346 | H36: 0.78004482 | I36: 0.87126711 | J36: 1.0274454 | K36: 1.1666849 | L36: 1.386758 | M36: 1.5029126 | N36: 1.6643796 | O36: 1.6924256 | P36: 1.8215122
A37: 1997 | B37: 0.015412472 | C37: 0.083028837 | D37: 0.20099867 | E37: 0.3000881 | F37: 0.36966814 | G37: 0.606303 | H37: 0.74987458 | I37: 0.86803151 | J37: 1.1443025 | K37: 1.2174555 | L37: 1.3488556 | M37: 1.5321503 | N37: 1.6015124 | O37: 1.6218681 | P37: 1.7962072
A38: 1998 | B38: 0.014883778 | C38: 0.076274765 | D38: 0.19454517 | E38: 0.31556663 | F38: 0.45714747 | G38: 0.52549741 | H38: 0.84027327 | I38: 0.93873483 | J38: 1.0123137 | K38: 1.0868388 | L38: 1.2627064 | M38: 1.3974489 | N38: 1.5188572 | O38: 1.8966153 | P38: 1.9089077
... A57: 2017 | B57: 0.020955314 | C57: 0.10407452 | D57: 0.25368745 | E57: 0.47203782 | F57: 0.63360879 | G57: 0.67283381 | H57: 0.75734475 | I57: 0.82078781 | J57: 0.90365743 | K57: 0.92189874 | L57: 1.0767442 | M57: 1.0311737 | N57: 1.2739006 | O57: 1.1479984 | P57: 1.5489652
A58: 2018 | B58: 0.022427235 | C58: 0.095396352 | D58: 0.22572931 | E58: 0.43454262 | F58: 0.59955499 | G58: 0.69586606 | H58: 0.77650392 | I58: 0.82630539 | J58: 0.93655477 | K58: 0.95807751 | L58: 1.0842715 | M58: 0.93573701 | N58: 1.5071627 | O58: NA | P58: 1.5194146
A59: 2019 | B59: 0.021557386 | C59: 0.1133557 | D59: 0.29701389 | E59: 0.50094768 | F59: 0.63674065 | G59: 0.74142539 | H59: 0.83064097 | I59: 0.94639468 | J59: 0.95985969 | K59: 1.0437957 | L59: 1.0124746 | M59: 1.0564222 | N59: 1.0424254 | O59: 1.2825423 | P59: NA
A60: 2020 | B60: NA | C60: NA | D60: NA | E60: NA | F60: NA | G60: NA | H60: NA | I60: NA | J60: NA | K60: NA | L60: NA | M60: NA | N60: NA | O60: NA | P60: NA
A61: 2021 | B61: 0.022498681 | C61: 0.10247386 | D61: 0.23874587 | E61: 0.44695999 | F61: 0.58457981 | G61: 0.71277143 | H61: 0.80419877 | I61: 0.85590952 | J61: 0.98023943 | K61: 1.1501008 | L61: 1.0649628 | M61: 1.1514638 | N61: 1.3125886 | O61: 1.0260876 | P61: 1.3824833
A62: 2022 | B62: 0.017285352 | C62: 0.11726235 | D62: 0.26733573 | E62: 0.44318865 | F62: 0.59097485 | G62: 0.70946782 | H62: 0.78059251 | I62: 0.88119506 | J62: 0.97573352 | K62: 1.0701158 | L62: 1.3270858 | M62: 1.3051274 | N62: 1.3562492 | O62: 1.2389392 | P62: 1.8623408
...

Sheet intro.dat
A1: Quantity | B1: 2023 | C1: 2024 | D1: 2024 | E1: 2025
A2: M | B2: (natural | C2: mortality | D2: rate, | E2: ages | F2: 3+) | G2: 0.3 | H2: 0.3 | I2: 0.3 | J2: 0.3
A3: Tier | B3: 1a | C3: 1a | D3: 1a | E3: 1a
A4: Projected | D4: 12389000 | E4: 11445000 | F4: 10184000 | G4: 9437000 | H4: t | I4: t
A5: Projected | B5: female | C5: spawning | D5: 4171000 | E5: 3944000 | F5: 3518000 | G5: 3255000 | M5: t
A6: 𝐵0 | D6: 6653000 | E6: 6653000 | F6: 6728000 | G6: 6728000 | I6: t
A7: 𝐵𝑚𝑠𝑦 | D7: 2674000 | E7: 2674000 | F7: 2689000 | G7: 2689000 | I7: t
A8: 𝐹𝑂𝐹 | B8: 𝐿 | D8: 0.491 | E8: 0.491 | F8: 0.422
A9: 𝑚𝑎𝑥𝐹𝐴𝐵𝐶 | D9: 0.434 | E9: 0.434 | F9: 0.379 | G9: 0.379
A10: 𝐹𝐴𝐵𝐶 | D10: 0.365 | E10: 0.365 | F10: 0.33 | G10: 0.33
A11: 𝑂𝐹 | B11: 𝐿 | D11: 3381000 | E11: 4639000 | F11: 3162000 | G11: 3449000 | H11: t | J11: t
A12: 𝑚𝑎𝑥𝐴𝐵𝐶 | D12: 2987000 | E12: 4099000 | F12: 2837000 | G12: 3095000 | I12: t
A13: 𝐴𝐵𝐶 | D13: 1910000 | E13: 2275000 | F13: 2313000 | G13: 2401000 | I13: t
A14: Status | D14: 2021 | E14: 2022
A15: Overfishing | B15: No | C15: n/a | D15: No | E15: n/a
A16: Overfished | B16: n/a | C16: No | D16: n/a | E16: No
A17: Approaching | B17: overfished | C17: n/a | D17: No | E17: n/a | F17: No
B20: Year | C20: M | D20: Tier | E20: Age3plus | F20: SSB | G20: B0 | H20: Bmsy | I20: Fofl | J20: MaxF | K20: Fabc | L20: OFL | M20: MaxABC | N20: ABC
B21: lastyr_this | C21: 0.3 | D21: 1a | E21: {=TRANSPOSE(F4:G4)} -> 10184000 | F21: {=TRANSPOSE(F5:G5)} -> 3518000 | G21: {=TRANSPOSE(F6:G6)} -> 6728000 | H21: {=TRANSPOSE(F7:G7)} -> 2689000 | I21: 0.491 | J21: 0.379 | K21: 0.33 | L21: {=TRANSPOSE(F11:G11)} -> 3162000 | M21: {=TRANSPOSE(F12:G12)} -> 2837000 | N21: {=TRANSPOSE(F13:G13)} -> 2313000
B22: lastyr_next | C22: 0.3 | D22: 1a | E22: 9437000 | F22: 3255000 | G22: 6728000 | H22: 2689000 | I22: 0.491 | J22: 0.379 | K22: 0.33 | L22: 3449000 | M22: 3095000 | N22: 2401000
F25: 4171000 | G25: 6653000 | H25: 2674000 | I25: 0.491 | J25: 0.434 | K25: 0.365 | L25: 3381000 | M25: 2987000 | N25: 1910000
F26: 3944000 | G26: 6653000 | H26: 2674000 | I26: 0.491 | J26: 0.434 | K26: 0.365 | L26: 4639000 | M26: 4099000 | N26: 2275000
H35: 2025 | I35: 2026
H36: 0.313 | I36: 0.313
H37: 5 | I37: 5
H38: 247137 | I38: 247137
H39: 0.313 | I39: 0.313
H40: 0.23475 | I40: 0.23475
H41: 0.23475 | I41: 0.23475
H42: =H38*M -> 77353.881 | I42: =H42 -> 77353.881
H43: =$H$40*H38 -> 58015.411 | I43: =H43 -> 58015.411
H44: =H43 -> 58015.411 | I44: =I43 -> 58015.411

Sheet pm_24.dat 
B1: #styr
B2: 1964
B3: #styr_bts
B4: 1982
B5: #styr_ats
B6: 1994
B7: #endyr
B8: 2024
B9: #recage
B10: 1
B11: #nages
B12: 15
B13: #p_mature
B14: 0 | C14: 0.008 | D14: 0.289 | E14: 0.641 | F14: 0.842 | G14: 0.901 | H14: 0.947 | I14: 0.963 | J14: 0.97 | K14: 1 | L14: 1 | M14: 1 | N14: 1 | O14: 1 | P14: 1
B15: #ew_ind
B16: 8 | C16: 7 | D16: 2 | E16: 9 | F16: 7 | G16: 7 | H16: 7 | I16: 7 | J16: 8 | K16: 6 | L16: 5 | M16: 7 | N16: 8 | O16: 8 | P16: 7 | Q16: 5 | R16: 4 | S16: 6 | T16: 7 | U16: 8 | V16: 3 | W16: 7 | X16: 7 | Y16: 7 | Z16: 7 | AA16: 8 | AB16: 4 | AC16: 6 | AD16: 2 | AE16: 1 | AF16: 6 | AG16: 6 | AH16: 4 | AI16: 4 | AJ16: 10 | AK16: 4 | AL16: 4 | AM16: 4 | AN16: 4 | AO16: 4 | AP16: 4 | AQ16: 4 | AR16: 4 | AS16: 4 | AT16: 4 | AU16: 4 | AV16: 4 | AW16: 4 | AX16: 4 | AY16: 4 | AZ16: 4 | BA16: 4 | BB16: 4 | BC16: 4 | BD16: 4 | BE16: 4 | BF16: 4 | BG16: 4 | BH16: 4 | BI16: 4 | BJ16: 4
B17: 5 | C17: 6 | D17: 6 | E17: 8 | F17: 5 | G17: 8 | H17: 5 | I17: 4 | J17: 8 | K17: 4 | L17: 5 | M17: 5 | N17: 6 | O17: 5 | P17: 8 | Q17: 11 | R17: 6 | S17: 7 | T17: 9 | U17: 10 | V17: 4 | W17: 4 | X17: 6 | Y17: 5 | Z17: 7 | AA17: 9 | AB17: 5 | AC17: 7 | AD17: 3 | AE17: 5 | AF17: 3 | AG17: 5 | AH17: 4 | AI17: 6 | AJ17: 11 | AK17: 4 | AL17: 4 | AM17: 4 | AN17: 4 | AO17: 4 | AP17: 4 | AQ17: 4 | AR17: 4 | AS17: 4 | AT17: 4 | AU17: 4 | AV17: 4 | AW17: 4 | AX17: 4 | AY17: 4 | AZ17: 4 | BA17: 4 | BB17: 4 | BC17: 4 | BD17: 4 | BE17: 4 | BF17: 4 | BG17: 4 | BH17: 4 | BI17: 4 | BJ17: 4
B18: #wt_fsh
A19: 1964 | B19: 0.0066 | C19: 0.17 | D19: 0.303 | E19: 0.447 | F19: 0.589 | G19: 0.722 | H19: 0.84 | I19: 0.942 | J19: 1.029 | K19: 1.102 | L19: 1.163 | M19: 1.212 | N19: 1.253 | O19: 1.286 | P19: 1.312
A20: =A19+1 -> 1965 | B20: 0.0066 | C20: 0.17 | D20: 0.303 | E20: 0.447 | F20: 0.589 | G20: 0.722 | H20: 0.84 | I20: 0.942 | J20: 1.029 | K20: 1.102 | L20: 1.163 | M20: 1.212 | N20: 1.253 | O20: 1.286 | P20: 1.312
A21: =A20+1 -> 1966 | B21: 0.0066 | C21: 0.17 | D21: 0.303 | E21: 0.447 | F21: 0.589 | G21: 0.722 | H21: 0.84 | I21: 0.942 | J21: 1.029 | K21: 1.102 | L21: 1.163 | M21: 1.212 | N21: 1.253 | O21: 1.286 | P21: 1.312
A22: =A21+1 -> 1967 | B22: 0.0066 | C22: 0.17 | D22: 0.303 | E22: 0.447 | F22: 0.589 | G22: 0.722 | H22: 0.84 | I22: 0.942 | J22: 1.029 | K22: 1.102 | L22: 1.163 | M22: 1.212 | N22: 1.253 | O22: 1.286 | P22: 1.312
A23: =A22+1 -> 1968 | B23: 0.0066 | C23: 0.17 | D23: 0.303 | E23: 0.447 | F23: 0.589 | G23: 0.722 | H23: 0.84 | I23: 0.942 | J23: 1.029 | K23: 1.102 | L23: 1.163 | M23: 1.212 | N23: 1.253 | O23: 1.286 | P23: 1.312
A24: =A23+1 -> 1969 | B24: 0.0066 | C24: 0.17 | D24: 0.303 | E24: 0.447 | F24: 0.589 | G24: 0.722 | H24: 0.84 | I24: 0.942 | J24: 1.029 | K24: 1.102 | L24: 1.163 | M24: 1.212 | N24: 1.253 | O24: 1.286 | P24: 1.312
A25: =A24+1 -> 1970 | B25: 0.0066 | C25: 0.17 | D25: 0.303 | E25: 0.447 | F25: 0.589 | G25: 0.722 | H25: 0.84 | I25: 0.942 | J25: 1.029 | K25: 1.102 | L25: 1.163 | M25: 1.212 | N25: 1.253 | O25: 1.286 | P25: 1.312
A26: =A25+1 -> 1971 | B26: 0.0066 | C26: 0.17 | D26: 0.303 | E26: 0.447 | F26: 0.589 | G26: 0.722 | H26: 0.84 | I26: 0.942 | J26: 1.029 | K26: 1.102 | L26: 1.163 | M26: 1.212 | N26: 1.253 | O26: 1.286 | P26: 1.312
A27: =A26+1 -> 1972 | B27: 0.0066 | C27: 0.17 | D27: 0.303 | E27: 0.447 | F27: 0.589 | G27: 0.722 | H27: 0.84 | I27: 0.942 | J27: 1.029 | K27: 1.102 | L27: 1.163 | M27: 1.212 | N27: 1.253 | O27: 1.286 | P27: 1.312
A28: =A27+1 -> 1973 | B28: 0.0066 | C28: 0.17 | D28: 0.303 | E28: 0.447 | F28: 0.589 | G28: 0.722 | H28: 0.84 | I28: 0.942 | J28: 1.029 | K28: 1.102 | L28: 1.163 | M28: 1.212 | N28: 1.253 | O28: 1.286 | P28: 1.312
A29: =A28+1 -> 1974 | B29: 0.0066 | C29: 0.17 | D29: 0.303 | E29: 0.447 | F29: 0.589 | G29: 0.722 | H29: 0.84 | I29: 0.942 | J29: 1.029 | K29: 1.102 | L29: 1.163 | M29: 1.212 | N29: 1.253 | O29: 1.286 | P29: 1.312
A30: =A29+1 -> 1975 | B30: 0.0066 | C30: 0.17 | D30: 0.303 | E30: 0.447 | F30: 0.589 | G30: 0.722 | H30: 0.84 | I30: 0.942 | J30: 1.029 | K30: 1.102 | L30: 1.163 | M30: 1.212 | N30: 1.253 | O30: 1.286 | P30: 1.312
A31: =A30+1 -> 1976 | B31: 0.0066 | C31: 0.17 | D31: 0.303 | E31: 0.447 | F31: 0.589 | G31: 0.722 | H31: 0.84 | I31: 0.942 | J31: 1.029 | K31: 1.102 | L31: 1.163 | M31: 1.212 | N31: 1.253 | O31: 1.286 | P31: 1.312
... A78: =A77+1 -> 2023 | B78: 0.025182262 | C78: 0.18622176 | D78: 0.492447 | E78: 0.481642 | F78: 0.524421 | G78: 0.605881 | H78: 0.79623 | I78: 0.919782 | J78: 0.955355 | K78: 1.045836 | L78: 1.088177 | M78: 1.267231 | N78: 1.354656 | O78: 1.325267 | P78: 0.950582
A79: =A78+1 -> 2024 | B79: 0.025182262 | C79: 0.18622176 | D79: ='wt24.rep'!B202 -> 0.401336 | E79: ='wt24.rep'!C202 -> 0.667373 | F79: ='wt24.rep'!D202 -> 0.662504 | G79: ='wt24.rep'!E202 -> 0.719546 | H79: ='wt24.rep'!F202 -> 0.790729 | I79: ='wt24.rep'!G202 -> 0.905068 | J79: ='wt24.rep'!H202 -> 1.009136 | K79: ='wt24.rep'!I202 -> 1.061077 | ... P79: ='wt24.rep'!N202 -> 1.368254
B80: #wt_ssb
A81: 1964 | B81: 0.084881666 | C81: 0.19586813 | D81: 0.31376279 | E81: 0.45929554 | F81: 0.5886236 | G81: 0.69781833 | H81: 0.79679874 | I81: 0.91486126 | J81: 1.056957 | K81: 1.1472315 | L81: 1.2901065 | M81: 1.3879179 | N81: 1.4316668 | O81: 1.4070027 | P81: 1.5228669
A82: =A81+1 -> 1965 | B82: 0.084881666 | C82: 0.19586813 | D82: 0.31376279 | E82: 0.45929554 | F82: 0.5886236 | G82: 0.69781833 | H82: 0.79679874 | I82: 0.91486126 | J82: 1.056957 | K82: 1.1472315 | L82: 1.2901065 | M82: 1.3879179 | N82: 1.4316668 | O82: 1.4070027 | P82: 1.5228669
A83: =A82+1 -> 1966 | B83: 0.084881666 | C83: 0.19586813 | D83: 0.31376279 | E83: 0.45929554 | F83: 0.5886236 | G83: 0.69781833 | H83: 0.79679874 | I83: 0.91486126 | J83: 1.056957 | K83: 1.1472315 | L83: 1.2901065 | M83: 1.3879179 | N83: 1.4316668 | O83: 1.4070027 | P83: 1.5228669
A84: =A83+1 -> 1967 | B84: 0.084881666 | C84: 0.19586813 | D84: 0.31376279 | E84: 0.45929554 | F84: 0.5886236 | G84: 0.69781833 | H84: 0.79679874 | I84: 0.91486126 | J84: 1.056957 | K84: 1.1472315 | L84: 1.2901065 | M84: 1.3879179 | N84: 1.4316668 | O84: 1.4070027 | P84: 1.5228669
A85: =A84+1 -> 1968 | B85: 0.084881666 | C85: 0.19586813 | D85: 0.31376279 | E85: 0.45929554 | F85: 0.5886236 | G85: 0.69781833 | H85: 0.79679874 | I85: 0.91486126 | J85: 1.056957 | K85: 1.1472315 | L85: 1.2901065 | M85: 1.3879179 | N85: 1.4316668 | O85: 1.4070027 | P85: 1.5228669
A86: =A85+1 -> 1969 | B86: 0.084881666 | C86: 0.19586813 | D86: 0.31376279 | E86: 0.45929554 | F86: 0.5886236 | G86: 0.69781833 | H86: 0.79679874 | I86: 0.91486126 | J86: 1.056957 | K86: 1.1472315 | L86: 1.2901065 | M86: 1.3879179 | N86: 1.4316668 | O86: 1.4070027 | P86: 1.5228669
...

Sheet Sheet9
C2: & | D2: 1 | E2: & | F2: 2 | G2: & | H2: 3 | I2: & | J2: 4 | K2: & | L2: 5 | M2: & | N2: 6 | O2: & | P2: 7 | Q2: & | R2: 8 | S2: & | T2: 9 | U2: & | V2: 10 | W2: & | X2: 11 | Y2: & | Z2: 12 | AA2: & | AB2: 13 | AC2: & | AD2: 14 | AE2: & | AF2: Sum | AG2: \\
B3: \hline
B4: 1979 | C4: & | D4: 101.4 | E4: & | F4: 543 | G4: & | H4: 719.8 | I4: & | J4: 420.1 | K4: & | L4: 392.5 | M4: & | N4: 215.5 | O4: & | P4: 56.3 | Q4: & | R4: 25.7 | S4: & | T4: 35.9 | U4: & | V4: 27.5 | W4: & | X4: 17.6 | Y4: & | Z4: 7.9 | AA4: & | AB4: 3 | AC4: & | AD4: 1.1 | AE4: & | AF4: =SUM(C4:AE4) -> 2567.3 | AG4: \\
B5: 1980 | C5: & | D5: 9.8 | E5: & | F5: 462.2 | G5: & | H5: 822.9 | I5: & | J5: 443.3 | K5: & | L5: 252.1 | M5: & | N5: 210.9 | O5: & | P5: 83.7 | Q5: & | R5: 37.6 | S5: & | T5: 21.7 | U5: & | V5: 23.9 | W5: & | X5: 25.4 | Y5: & | Z5: 15.9 | AA5: & | AB5: 7.7 | AC5: & | AD5: 3.7 | AE5: & | AF5: =SUM(C5:AE5) -> 2420.8 | AG5: \\
